Workbook

Sheet Contributors
A1: Terms describing "roles" or"personas" in FAIR data principle implementation. These are all "stakeholders" in FAIR data principles implementation. The purpose of this document is to collect data that will be sued to update the FAIR maturity matrix framework as well as the FAIR business framework.
B2: Name | C2: Last/Family_Name | D2: Organisation | E2: ORCID | F2: comments | G2: Initials
B3: Ranu | C3: ⁠Sharma | D3: AbbVie | E3: https://orcid.org/0009-0004-6207-0773 | G3: RS
B4: Debashree | C4: Chakrabarti | D4: ABBVIE | E4: {enter your ORCID - takes 2 min to create one} | G4: DC
B5: Kathleen | C5: Rand | D5: AMGEN | E5: {enter your ORCID - takes 2 min to create one} | G5: Amgen
B6: Philippe | C6: Rocca-Serra | D6: Astrazeneca | E6: {enter your ORCID - takes 2 min to create one} | G6: PRS
B7: Baptiste | C7: Tauzin | D7: CSL-Behring | E7: {enter your ORCID - takes 2 min to create one} | G7: BT
B8: Lynch | C8: Nick | D8: Curlew Research | E8: https://orcid.org/0000-0002-8997-5298 | G8: NL
B9: Avinash | C9: Dixit | D9: Datavid | E9: https://orcid.org/0009-0005-8204-6655 | G9: AD
B10: Ted | C10: Slater | D10: EPAM | E10: https://orcid.org/0000-0003-1386-0731 | G10: TS
B11: Buck | C11: Flannigan | D11: Fluree
B12: David | C12: Fernandez Rue | D12: Gruenenthal | E12: https://0009-0007-6684-2605 | G12: DFR
B13: Nalini | C13: Mehta | D13: GSK | E13: https://orcid.org/0000-0002-7553-6569 | G13: NM
B14: Emiliano | C14: Reynares | D14: IQVIA | E14: {enter your ORCID - takes 2 min to create one} | G14: ER
B15: Katharina | C15: Lang | D15: Novo Nordisk | E15: {enter your ORCID - takes 2 min to create one} | G15: KHRL
B16: Karien | C16: Pype | D16: Ontoforce | E16: {enter your ORCID - takes 2 min to create one} | G16: Ontoforce
B17: Chris | C17: Day | D17: Perdl | E17: {enter your ORCID - takes 2 min to create one} | G17: CD
B18: Birgit | C18: Meldal | D18: Pfizer | E18: https://orcid.org/0000-0003-4062-6158 | G18: BM
B19: Giovanni | C19: Nisato | D19: Pistoia Alliance | E19: https://orcid.org/0000-0002-5824-0061 | G19: GN
B20: Tara Kumar | C20: Gajula | D20: Takeda | E20: https://orcid.org/0009-0006-0072-7148 | G20: TKG
B21: John Apathy | C21: Apathy | D21: Xponentl | E21: {enter your ORCID - takes 2 min to create one} | G21: JA

Sheet FAIR_principles_GOFAIR
A1: Source: | B1: https://www.go-fair.org/fair-principles/
A2: Accessed on_YYYY_MM_DD: | B2: 45818
A3: Findable | C3: =A3 -> Findable
A4: The first step in (re)using data is to find them. Metadata and data should be easy to find for both humans and computers. Machine-readable metadata are essential for automatic discovery of datasets and services, so this is an essential component of the FAIRification process.
A5: F1. (Meta)data are assigned a globally unique and persistent identifier | C5: =LEFT(A5,2) -> F1 | D5: =RIGHT(A5,LEN(A5)-4) -> (Meta)data are assigned a globally unique and persistent identifier
A6: F2. Data are described with rich metadata (defined by R1 below) | C6: =LEFT(A6,2) -> F2 | D6: =RIGHT(A6,LEN(A6)-4) -> Data are described with rich metadata (defined by R1 below)
A7: F3. Metadata clearly and explicitly include the identifier of the data they describe | C7: =LEFT(A7,2) -> F3 | D7: =RIGHT(A7,LEN(A7)-4) -> Metadata clearly and explicitly include the identifier of the data they describe
A8: F4. (Meta)data are registered or indexed in a searchable resource | C8: =LEFT(A8,2) -> F4 | D8: =RIGHT(A8,LEN(A8)-4) -> (Meta)data are registered or indexed in a searchable resource
A9: Accessible | C9: =A9 -> Accessible
A10: Once the user finds the required data, she/he/they need to know how they can be accessed, possibly including authentication and authorisation.
A11: A1. (Meta)data are retrievable by their identifier using a standardised communications protocol | C11: =LEFT(A11,2) -> A1 | D11: =RIGHT(A11,LEN(A11)-4) -> (Meta)data are retrievable by their identifier using a standardised communications protocol
A12: A1.1 The protocol is open, free, and universally implementable | C12: =LEFT(A12,4) -> A1.1 | D12: =RIGHT(A12,LEN(A12)-5) -> The protocol is open, free, and universally implementable
A13: A1.2 The protocol allows for an authentication and authorisation procedure, where necessary | C13: =LEFT(A13,4) -> A1.2 | D13: =RIGHT(A13,LEN(A13)-5) -> The protocol allows for an authentication and authorisation procedure, where necessary
A14: A2. Metadata are accessible, even when the data are no longer available | C14: =LEFT(A14,2) -> A2 | D14: =RIGHT(A14,LEN(A14)-4) -> Metadata are accessible, even when the data are no longer available
A15: Interoperable | C15: =A15 -> Interoperable
A16: The data usually need to be integrated with other data. In addition, the data need to interoperate with applications or workflows for analysis, storage, and processing.
A17: I1. (Meta)data use a formal, accessible, shared, and broadly applicable language for knowledge representation. | C17: =LEFT(A17,2) -> I1 | D17: =RIGHT(A17,LEN(A17)-4) -> (Meta)data use a formal, accessible, shared, and broadly applicable language for knowledge representation.
A18: I2. (Meta)data use vocabularies that follow FAIR principles | C18: =LEFT(A18,4) -> I2. | D18: =RIGHT(A18,LEN(A18)-5) -> Meta)data use vocabularies that follow FAIR principles
A19: I3. (Meta)data include qualified references to other (meta)data | C19: =LEFT(A19,4) -> I3. | D19: =RIGHT(A19,LEN(A19)-5) -> Meta)data include qualified references to other (meta)data
A20: Reusable | C20: =A20 -> Reusable
A21: The ultimate goal of FAIR is to optimise the reuse of data. To achieve this, metadata and data should be well-described so that they can be replicated and/or combined in different settings.
A22: R1. (Meta)data are richly described with a plurality of accurate and relevant attributes | C22: =LEFT(A22,2) -> R1 | D22: =RIGHT(A22,LEN(A22)-4) -> (Meta)data are richly described with a plurality of accurate and relevant attributes
A23: R1.1. (Meta)data are released with a clear and accessible data usage license | C23: =LEFT(A23,4) -> R1.1 | D23: =RIGHT(A23,LEN(A23)-5) -> (Meta)data are released with a clear and accessible data usage license
A24: R1.2. (Meta)data are associated with detailed provenance | C24: =LEFT(A24,4) -> R1.2 | D24: =RIGHT(A24,LEN(A24)-5) -> (Meta)data are associated with detailed provenance
A25: R1.3. (Meta)data meet domain-relevant community standards | C25: =LEFT(A25,4) -> R1.3 | D25: =RIGHT(A25,LEN(A25)-5) -> (Meta)data meet domain-relevant community standards
A26: The principles refer to three types of entities: data (or any digital object), metadata (information about that digital object), and infrastructure. For instance, principle F4 defines that both metadata and data are registered or indexed in a searchable resource (the infrastructure component).

Sheet 2025-Personas-FAIR-cleaned
A1: URL/URI of the FAIRpersona | B1: short name of the role [text] | D1: Definition of the role, text. Ideally, this is the same as a known, existing definition we can refer to publicly. | E1: identification of the person that added content in a given line in this document. For internal use, not for ppublic disclosure. | F1: URL/ URI of the text of the definition. (this is a Nice to have for FAIR Maturity Matrix documentation. ) | G1: Known synonyms of this role. Nice to have for FAIR Maturity Matrix documentation. | H1: List of related roles - no hierarchy. Nice to have for FAIR Maturity Matrix documentation and for the FAIR Business Value frame. | I1: Usage in different organisations; non exahustive, just some examples. Nice to have. | J1: Version of the FAIR Maturity Matrix in which this role appears, or recommendation to add to a new version. Based on FAIR expert inputs (organize session for this) | K1: What are the typical tasks, activities or "jobs" of the persona. | L1: Description of the challenges a given persona has with data. | M1: What benefits can FAIR data bring to the persona. | N1: Is the persona necessary in the FAIR MM ? Is it a duplicate? Can it be merged with another persona? | O1: Description of the challenges a given persona has with data. | P1: What benefits can FAIR data bring to the persona. | Q1: document expert group recommendation
A2: FAIRMM-link-MD | B2: Label_persona | C2: Primary data role producer/enabler/consumer | D2: description_of_role | E2: Contributors | F2: Source URL/URI | G2: Synonyms | H2: Related persona | I2: Notes on usage, relation to other roles or personas | J2: FAIRMM-version | K2: Persona_tasks | L2: Issues_latent_gains_draft | M2: Potential_FAIR_benefits_Narrative | N2: Editing comments - Must have/ nice to have / park for the moment | O2: Issues_Latent_gains__Final | P2: Specific-FAIR_benefits_ | Q2: Expert_recommendation_comment | R2: notes | S2: notes2 | T2: notes3
A3: https://github.com/PistoiaAlliance/FAIRMaturityMatrix/blob/FAIR-MM-V1.2/FAIR_personas/Business_analyst.md | B3: Business_Analyst | C3: Data Consumer | D3: The Business Analyst serves as a vital link between business stakeholders and technical teams, ensuring that data, systems, and processes align with organizational goals. They analyze and document business requirements, translate them into data models and workflows, and collaborate across functions to ensure cohesive data design and governance. Skilled in process analysis, requirements engineering, and stakeholder communication, they enable informed decision-making by promoting data quality, consistency, and effective change management. | E3: Avinash Dixit, Debashree Chakrabarti [GN'] | F3: DAMA-DMBOK2: Roles & Responsibilities | G3: Data Modeller; Business System Consultant; Business Relationship Manager; Data Analyst | H3: Advanced_Data_Analysis_and_Insights_Professional,Business_Analyst,Business_Owner,Data_Analyst | I3: Used at : AstraZeneca, Abbvie | J3: { To review with group - V1.2 } | K3: The Business Analyst collaborates across R&D, clinical, regulatory, and IT teams to gather requirements, map workflows, and identify opportunities for process and data improvement. They design compliant data models and specifications, ensure alignment with governance standards, and validate data quality. Additionally, they document processes, support change management, and monitor solution performance to drive continuous improvement in data-driven operations. | L3: Legacy platforms incompatible with new technology. Scientists / users of technology fail to prioritize upkeep. | M3: Business Analyst in a pharmaceutical company, adopting FAIR principles transforms data management into a scalable, proactive discipline. Findable and Accessible data reduce redundancy by eliminating silos and duplication of effort, while Interoperable data—structured through shared ontologies—prevents vendor lock-in and enables seamless integration across diverse platforms and partners. Reusable and well-documented datasets support reproducibility, compliance, and efficient lifecycle management, allowing petabytes of research, clinical, and manufacturing data to be managed and archived systematically through defined policies. With FAIR in place, the Business Analyst can focus on driving business value—optimizing processes, improving data quality, and ensuring that insights are derived from consistent, traceable, and reusable information across the enterprise. | N3: {[GN] should this role be defined more broadly? | O3: Issues: fragmented data silos, poor metadata, inconsistent standards, and limited interoperability—leading to rework, inefficiencies, compliance risks, and slow decision-making. Latent gains: improve data discoverability, consistency, and traceability; reducing redundancy and vendor lock-in; and enabling efficient management of large, diverse datasets through shared ontologies and archiving policies. Increase ability to work proactively, streamline workflows, ensure regulatory readiness, and deliver faster, more reliable insights across the R&D and product lifecycle. | P3: F2 improves discoverability of datasets for analytical use; A1.1 provides standardized metadata protocols for access; R1.2 ensures lawful reuse through explicit licensing clarity
A4: https://github.com/PistoiaAlliance/FAIRMaturityMatrix/blob/FAIR-MM-V1.2/FAIR_personas/Business_Leader.md | B4: Business_Leader | C4: Data Consumer | D4: In an organization, personnel holding roles such as CEO, CFO, CTO, COO, or Functional Line Leaders with executive and strategy level decision- making capacities. | E4: John Apathy, giovanni.nisato / Karien Pype | F4: https://www.wikidata.org/wiki/Q484876 | G4: Chief Executive Officer (CEO); Chief Operating Officer (COO); Chief Financial Officer (CFO); Functional Line Leader; Head of R&D; Head of Manufacturing; Head of CMC; Head of Supply Chain Operations; | H4: Business_Analyst,Business_Leader,Business_Owner,Project_Manager,Technology_Leader | I4: Used at: all companies | J4: { To review with group - V1.2 } | K4: Making data-driven strategic decisions, performance and KPI management, engaging with investors and stakeholders with reliable data, enabling digital and data transformation, managing risk and compliance, supporting M&A, licensing, and due diligence | L4: Data fragmentation, data in silos, poor data re-usability, lack in visibility into data (which data do we have? Can we trust it?), barriers for scaling AI/ML initiatives, compliance and data governance risks | M4: For Business Leaders in a pharmaceutical company, implementing FAIR data principles delivers strategic, operational, and financial advantages: 1- establish a foundation for digital transformation, enabling enterprise-wide data integration across R&D, manufacturing, regulatory, and commercial operations. Executives gain trusted, real-time visibility into the organization’s data assets, accelerating strategic decision-making and reducing dependency on fragmented systems or manual reporting. 2- drive innovation and speed-to-market by making high-quality data readily reusable for AI, machine learning, and predictive modeling—shortening development cycles, improving clinical trial design, and identifying portfolio opportunities faster. 3- reduce operational costs and risks by minimizing data duplication, automating data governance, and enabling scalable management of petabytes of information under consistent standards and archiving policies. 4- enhance regulatory compliance, audit readiness, and partner interoperability, positioning the organization as a trusted, data-driven leader in a rapidly evolving digital health ecosystem. | N4: must have | O4: Issues: Data fragmentation, data in silos, poor data re-usability, lack in visibility into data (which data do we have? Can we trust it?), barriers for scaling AI/ML initiatives, compliance and data governance risks. Latent gains: implementing FAIR principles would reduce these challenges and unlock efficiency, compliance, and reuse. | P4: F1. Enables enterprise-wide data traceability and eliminates duplication, giving executives visibility and accountability for all critical data assets. ; F2. Improves data discoverability and context, accelerating evidence-based decision-making across R&D, clinical, and manufacturing domains.; F3. Strengthens data lineage and provenance, ensuring trustworthy, audit-ready information for regulatory compliance.; F4. Provides centralized visibility of data assets through searchable catalogs and dashboards for strategic oversight and resource planning.; A1. Ensures consistent, standardized access to validated data across systems, reducing manual effort and delays.; A2. Balances open access with secure authorization, protecting intellectual property and patient data while enabling collaboration.; I1. Promotes seamless data exchange across functions, reducing vendor lock-in and integration costs.; I2. Standardizes vocabularies and formats, supporting scalable data governance and automation at petabyte scale.; I3. Connects datasets through qualified references, revealing relationships across the value chain for portfolio and pipeline optimization.;R1. Ensures data are complete, accurate, and meaningful for reuse in analytics, AI, and digital innovation.; R1.1. Clarifies data usage rights, reducing legal uncertainty and enabling confident external collaboration.; R1.2. Provides full provenance for audit trails, reinforcing data integrity and regulatory readiness.; R1.3. Aligns data with community and regulatory standards (e.g., CDISC, IDMP), ensuring compliance and interoperability.;
A5: https://github.com/PistoiaAlliance/FAIRMaturityMatrix/blob/FAIR-MM-V1.2/FAIR_personas/Business_Owner.md | B5: Business_Owner | C5: Data Consumer | D5: The Business Owner is an executive-level business role accountable for the value, performance, and strategic success of a defined business process, product, system, or dataset. As the designated authority within their domain, the Business Owner ensures that data and processes deliver measurable business value, meet defined KPIs, and align with organizational objectives and regulatory requirements. In accordance with DAMA-DMBOK2, the Business Owner is responsible for defining business requirements, approving data standards and policies, and ensuring that data is managed as a strategic enterprise asset. They collaborate with Data Stewards, Architects, and IT teams to translate business needs into data capabilities, oversee the quality and fitness-for-purpose of data, and drive continuous improvement. By championing sound data governance and FAIR-aligned practices, the Business Owner ensures that information assets are consistent, compliant, and reusable—enabling efficient decision-making, regulatory confidence, and sustained business value generation across the organization. | E5: Kathleen Rand , Chris Day / GN re-editing | F5: DAMA-DMBOK2: Appendix A: Roles & Responsibilities Matrix | G5: Business Data Owner; Data Asset Owner; Business Executive & Manager; Executive Sponsor; | H5: FAIR_Data_Architect,Business_Analyst,Data_Analyst,Business_Leader,Data_Owner,Data_Standards_and_Governance_Expert,Subject_Matter_Expert,Project_Manager | I5: Used at : Amgen Used within DAMA DMBoKV2 | J5: { To review with group - V1.2 } | K5: The Business Owner performs a set of core tasks that ensure data, processes, and systems within their domain deliver measurable business value and align with corporate and regulatory expectations. Their tasks include defining business requirements and objectives for data and digital initiatives, ensuring they support strategic priorities. They evaluate and track business value and KPIs, measuring the performance and success of data-driven processes and products. The Business Owner also approves and enforces data policies, standards, and quality rules, guaranteeing that information is accurate, complete, and business-ready. They collaborate with Data Stewards, Data Architects, and IT teams to translate business needs into practical governance and data management solutions. Additionally, they prioritize and sponsor data initiatives, allocate resources, and resolve cross-functional challenges related to data ownership, access, and quality—driving continuous improvement and ensuring that data assets contribute directly to organizational goals. | L5: 1. Unclear Business Ownership of Data Assets FAIR View: Without clear ownership, stewardship for making data Findable, Accessible, Interoperable, and Reusable is often neglected. DAMA View: Data Ownership (within Data Governance) must be clearly defined, yet business owners are often unaware or unclear about their responsibilities. Impact: Data is treated as a by-product, not an asset, hindering strategic data enablement. 2. Lack of Alignment Between Business Goals and Data Strategy FAIR View: FAIRification efforts may be driven by IT or compliance teams, not aligned with value streams or KPIs that matter to business owners. DAMA View: Poor alignment across Data Strategy, Business Process Management, and Data Governance. Impact: Investments in FAIR may appear technical or academic, with unclear ROI for the business owner. 3. Data is Not Trusted or Understood FAIR View: If metadata and provenance are absent or poor, trust is undermined. DAMA View: Data Quality and Metadata Management are foundational, yet often fragmented. Impact: Business owners cannot rely on data for critical decision-making, reducing willingness to sponsor data initiatives. 4. Inconsistent Data Accessibility Across Functions FAIR View: Access policies are inconsistent, siloed, or not machine-actionable. DAMA View: Access & Security Management is often reactive, not driven by business use cases. Impact: Business owners encounter roadblocks or delays when accessing the data they are accountable for, impacting operational agility. 5. Data Silos Obstruct Reuse and Interoperability FAIR View: Poor interoperability blocks data integration and reuse across functions or systems. DAMA View: Reference and Master Data Management is often insufficient, leading to duplication and reconciliation overhead. Impact: Business owners can't extract cross-domain insights or scale analytics and AI initiatives. 6. Lack of Skills and Capacity to Interpret FAIR Metrics FAIR View: Maturity assessments and metrics may seem abstract or disconnected from business outcomes. DAMA View: Literacy gaps in both data management and data value communication. Impact: Business owners struggle to justify ongoing FAIR investment or demonstrate value to executive stakeholders. 7. Regulatory and Compliance Burden without Strategic Leverage FAIR View: Compliance is often a reactive cost centre rather than an opportunity to enhance FAIR maturity. DAMA View: Regulatory alignment is part of Governance and Risk Management but is rarely used as a FAIR catalyst. Impact: FAIR seen as a cost rather than a business enabler, unless reframed. 8. No Clear Business Value Framework for FAIR Data FAIR View: FAIR Maturity Models exist, but are not always coupled to business value frameworks like VMM or ROI calculations. DAMA View: Business Value Realisation is often implicit and not operationalised within Data Governance. Impact: Business owners cannot link FAIR efforts to quantifiable business drivers (e.g. revenue, speed to market, cost reduction). | M5: For a Business Owner, adopting FAIR data principles delivers both strategic and operational value by turning data into a reliable, reusable business asset. Findable and Accessible data accelerate evidence-based decision-making and reduce time spent locating or validating information, improving responsiveness and time-to-market. Enhanced metadata and provenance increase trust, data quality, and regulatory compliance while reducing audit risk and operational errors. Interoperable data promote collaboration and cross-functional reporting, supporting integration during organizational changes or mergers. Through reusability, FAIR minimizes data duplication, lowers operational costs, and improves ROI on data investments. By making data machine-actionable, FAIR enables automation, AI, and innovation, enhancing forecasting, modeling, and digital transformation. Finally, improved traceability and lifecycle stewardship reinforce transparency, governance, and enterprise resilience. Together, these capabilities empower the Business Owner to maximize business value, ensure compliance, and drive sustainable growth. | N5: must have | O5: Issues: Business Owners often face unclear accountability for data assets, leading to neglected stewardship and missed opportunities. Data is frequently treated as a by-product rather than a strategic asset, limiting its contribution to business value. Inconsistent metadata, poor provenance, and fragmented data quality management erode trust and make data unreliable for decision-making. Access policies are uneven and siloed, hindering operational agility, while weak interoperability and duplicate datasets prevent cross-domain insight generation. Additionally, limited literacy in FAIR principles and data governance frameworks leaves Business Owners unable to interpret metrics or demonstrate value. As a result, compliance efforts become reactive cost centers, and FAIR maturity remains disconnected from measurable business outcomes. Paradoxically, even FAIR initiatives aimed to improve the sitation may be driven by IT or compliance functions without alignment to core business goals or KPIs, creating the perception of limited ROI. Latent Gains: Implementing FAIR principles establishes clear business data ownership and embeds stewardship as a core governance function. Data becomes an enterprise asset: traceable, high-quality, and aligned with business objectives. Standardized metadata, access protocols, and interoperable systems ensure consistency, trust, and agility across departments. FAIR maturity strengthens regulatory compliance, turning oversight into strategic advantage through transparent provenance and auditability. Empowered by reliable, well-documented data, Business Owners can link FAIR investments directly to performance indicators such as reduced time-to-insight, faster innovation cycles, and lower operational risk. With improved data literacy and measurable ROI, FAIR transforms data management from a technical exercise into a business enabler, driving sustained efficiency, compliance, and value creation across the organization. | P5: F1 provides persistent identifiers that ensure KPIs and metrics are based on unambiguous, trusted datasets; A1 guarantees reliable access to the data needed for monitoring performance and driving improvements; R1.1 ensures reproducibility of results so business decisions can be defended and audited; R1.2 clarifies licensing and reuse conditions, enabling safe and efficient exploitation of data assets for innovation and partnerships.
A6: https://github.com/PistoiaAlliance/FAIRMaturityMatrix/blob/FAIR-MM-V1.2/FAIR_personas/Citizen_Data_Scientist.md | B6: Citizen_Data_Scientist | C6: Data Producer | D6: Non-expert business user applying self-service analytics tools and dashboards; highly competent but not data-science trained. Individual within an organization who, despite lacking formal training in data science, utilizes data analysis tools and techniques to extract insights from data. These individuals often come from various backgrounds, such as business, marketing, or operations, and possess domain-specific expertise. Citizen Data Scientists leverage self-service analytics platforms, intuitive data visualization tools, and automated machine learning algorithms to explore datasets, generate reports, and uncover patterns or trends relevant to their roles. | E6: giovanni.nisato@pistoiaalliance.org/ Emiliano Reynares / Debashree Chakrabarti | F6: https://pistoiaalliance.github.io/FAIRMaturityMatrix/resources_lexicon | G6: R&D Data Scientist; Applied Data Scientist; ML Scientist | H6: Advanced_Data_Analysis_and_Insights_Professional,Citizen_Data_Scientist,Legal_Data_Expert,Researcher | I6: CDS role will be empowered by GenAI, since natural languages interfaces and automation will lower technical barriers to build models, analyze data, and generate insights. | J6: FAIRMM_V1.1 | K6: Explores and visualize data, combines and clean data in collaboration with data teams, build dashboards, applies automated machine learning, and interpretes results to support business decisions. Performs all of the above using self-service tools without needing to code. | L6: 1. Sources of information lacking complete dataset 2. Context is missed or misinterpreted 3. Often requires additional SME to verify the reports generated, track down original data owners | M6: FAIR principles transforms how data can be accessed, understood, and used. FAIR data ensures that relevant datasets are findable and well-documented, allowing non-technical users to quickly locate trustworthy information without relying on data specialists. With accessible and standardized formats, self-service analytics tools and dashboards can easily connect to validated data sources, reducing the need for manual preparation or IT intervention. Interoperable data, structured through shared vocabularies and ontologies, ensures that metrics and definitions are consistent across business units—making analyses more reliable and comparable. Finally, reusable and well-described data enable repeatable analyses, support automation through AI-assisted tools, and foster confident, compliant decision-making. In short, FAIR empowers Citizen Data Scientists to work independently and efficiently, transforming domain expertise into actionable, data-driven insights without compromising data quality or governance. | O6: Issues: Information sources often lack complete datasets, leading to gaps and inconsistencies. Context is frequently missed or misinterpreted, making analysis and reporting unreliable. Project teams often need to involve additional subject matter experts to verify reports or trace original data owners. Latent gains: Implementing FAIR principles would minimize these challenges by improving data completeness, contextual clarity, and traceability—unlocking greater efficiency, compliance, and data reuse. | P6: F1 ensures that self-service tools pull from datasets with persistent identifiers, avoiding confusion and duplication; F2 provides rich metadata so non-expert users can quickly assess relevance, context, and quality of datasets; A1 guarantees seamless access to trusted data products without technical barriers; I1 enables smooth integration of datasets from different domains into dashboards and tools; R1.1 assures reproducibility of results, giving confidence that insights drawn from self-service analytics are reliable and defensible.
A7: https://github.com/PistoiaAlliance/FAIRMaturityMatrix/blob/FAIR-MM-V1.2/FAIR_personas/Clinical_Data_Manager.md | B7: Clinical_Data_Manager | C7: Data Producer | D7: Ensures accuracy, integrity, and reliability of data collected during clinical trials. They are responsible for designing and maintaining data management plans, overseeing data collection systems, and implementing quality control processes to ensure compliance with regulatory standards and requirements (e.g. from FDA,EMA). They manage the end-to-end data lifecycle in clinical trials. | E7: Ranu Sharma/ Giovanni Nisato ; AD | F7: http://purl.obolibrary.org/obo/NCIT_C142438 AND http://purl.obolibrary.org/obo/NCIT_C51820 | G7: Clinical Data Lead; CDISC Specialist; Clinical Informatics Lead | H7: Business_Owner,Data_manager,Lab_Manager,Project_Manager | I7: Used at AbbVie | J7: { To review with group - V1.2 } | K7: Clinical Data Manager (CDM) plays a central role in ensuring that clinical trial data is complete, accurate, and compliant with global regulatory standards. Their responsibilities include designing and managing case report forms (CRFs), overseeing electronic data capture (EDC) systems, validating incoming data from multiple sites, transforming raw data into standardized submission formats such as CDISC SDTM and ADaM. They coordinate with biostatisticians, clinical operations, medical writers, and regulatory teams to ensure data consistency, timeliness, and readiness for regulatory submissions across complex, multi-country studies. CDMs also monitor data integrity, manage queries and discrepancies, and document all processes to maintain an auditable trail. | L7: face substantial challenges due to the scale and complexity of their trials. Data often comes from heterogeneous sources, including EDCs, laboratory systems, imaging platforms, wearables, and patient-reported outcomes, each using different formats, terminologies, and standards. Reconciling these sources is time-intensive, error-prone, and requires extensive manual mapping. Inconsistent metadata, limited provenance tracking, and siloed data systems make it difficult to ensure data quality, traceability, and reuse across studies. These challenges can lead to delays in submissions, increase operational risk, and limit the ability to leverage historical data for future trials or real-world evidence generation. | M7: By ensuring that data and metadata are findable, accessible, interoperable, and reusable, Clinical_Data_Manager can automate and accelerate data integration and cleaning processes. Standardized vocabularies and ontologies facilitate cross-study comparisons and reduce mapping errors, while rich provenance tracking enhances audit readiness and regulatory confidence. FAIR data also enables better reuse of clinical trial datasets for secondary research, machine learning, and meta-analyses, ultimately supporting faster decision-making, reducing redundancy, and increasing the value derived from every clinical trial. | N7: must have | O7: Issues: face challenges due to the scale and complexity of their trials. Data often comes from heterogeneous sources, including EDCs, laboratory systems, imaging platforms, wearables, and patient-reported outcomes, each using different formats, terminologies, and standards. Reconciling these sources is time-intensive, error-prone, and requires extensive manual mapping. Inconsistent metadata, limited provenance tracking, and siloed data systems make it difficult to ensure data quality, traceability, and reuse across studies. These challenges can lead to delays in submissions, increase operational risk, and limit the ability to leverage historical data for future trials or real-world evidence generation. Latent gains: implementing FAIR principles would reduce these challenges and unlock efficiency, compliance, and reuse. | P7: F1 ensures patient and study data are persistently identified, enabling full traceability across trial phases; F2 provides rich metadata that documents study protocols, variables, and context for regulatory submissions; Findable (F1–F4): Standardized metadata and dataset identifiers make clinical trial data easier to locate across studies, sites, and systems. This ensures that data can be efficiently discovered for ongoing trials, regulatory submissions, or secondary research; A1 guarantees secure but reliable access to trial data for authorized stakeholders, maintaining audit trails and compliance with privacy regulations (GDPR, HIPAA); A2 Metadata remains accessible even if the underlying data is restricted, supporting transparency and planning; I1 supports interoperability between clinical trial management systems, EDC platforms, and regulatory systems ; I3 Adoption of CDISC standards, controlled vocabularies (MedDRA, SNOMED CT), and ontologies. Reduces mapping errors and allows cross-study comparisons and multi-study analyses; R1.1 ensures reproducibility of trial records and analyses, meeting strict compliance requirements; R1.3: Well-documented provenance, data quality metrics, and usage licenses make datasets suitable for regulatory submissions, meta-analyses, and machine learning applications. This increases the long-term value of clinical data and supports reproducibility.
A8: https://github.com/PistoiaAlliance/FAIRMaturityMatrix/blob/FAIR-MM-V1.2/FAIR_personas/Curator.md | B8: Curator | C8: Data Enabler | D8: Organizes, standardises, integrates, and maintains ontologies, vocabularies, datasets and data products to ensure they are FAIR and aligned with governance standards. | E8: Birgit Meldal | F8: Copilot and Birgit: http://purl.obolibrary.org/obo/NCIT_C69141 https://www.wikidata.org/wiki/Q674426 | G8: Data Curator; Biocurator; Knowledge Curator | H8: Data_Standards_and_Governance_Expert,Data_Steward,Knowledge-Enabled_Citizen,Ontologist | I8: Usage in different organisations | J8: { To review with group - V1.2 } | K8: designs and implements curation guidelines; works very closely with stewards and governance personas | L8: data are not aligned or based on domain/global standards. This creates additional work at the very least. | M8: FAIR data principles enhance the efficiency and impact of knowledge management. Rich metadata improves dataset discoverability and context, ensuring curated assets are easily found and understood. Interoperability across knowledge sources enables consistent integration and alignment, while adherence to community standards promotes the reuse and long-term value of curated data assets. | N8: must have | O8: Issues: data are not aligned or based on domain/global standards. This creates additional work at the very least.. Latent gains: implementing FAIR principles would reduce these challenges and unlock efficiency, compliance, and reuse. | P8: F2 enriches metadata to improve dataset discoverability; I1 ensures compatibility across curated knowledge sources; R1.3 promotes reuse of curated assets via community standards
A9: https://github.com/PistoiaAlliance/FAIRMaturityMatrix/blob/FAIR-MM-V1.2/FAIR_personas/Data_Analyst.md#description-of-fair-benefits-fordata_analyst | B9: Data_Analyst | C9: Data Consumer | D9: [RS]: Data Analyst is responsible for designing, developing, and maintaining dashboards and recurring reports that support business needs. Leveraging FAIR data principles, this role collects, cleans, and integrates high-quality data into analytical models and data pipelines. The Data Analyst ensures data is well-documented, traceable, and accessible for a variety of stakeholders, enabling robust analysis and clear, actionable insights for strategic decision-making. Additionally, they collaborate with data engineers and business partners to continuously improve data processes, enhance data usability, and maximize the value of analytics within the organization. | E9: Ranu Sharma, Ted Slater | F9: https://www.wikidata.org/wiki/Q77293133 | G9: Data Scientist; Insights Analyst; Business Intelligence Analyst; Data Analysis and Insights Manager; Senior Data Analyst; Real World Evidence Specialist; Real World Data Analyst; Health Data Manager Real World Data Analyst; Health Data Manager | H9: Advanced_Data_Analysis_and_Insights_Professional,Business_Analyst,Data_Analyst,Data_Integration_Specialist,Data_Owner | I9: Used at AbbVie | J9: { To review with group - V1.2 } | K9: [RS]: Data Analyst sources, prepares, and integrates data from multiple systems into analytical models and pipelines, ensuring data quality and accessibility. They build and maintain dashboards and reports, verify outputs for accuracy, and make insights available to stakeholders. The role also promotes FAIR data principles and collaborates with others to improve data processes and usability. | L9: Unexpected issues in source data; lack of documentation or metadata in source data; problems with workflows, pipelines, or models | M9: Supports FAIR data implementation by ensuring data is consistently documented with comprehensive metadata to enhance findability and reusability. They also facilitate data integration and interoperability by adhering to standardized data formats and collaborating with other teams to optimize data accessibility. {()} {[( F1, A1, I1, R1.1 )]} – F1 provides general benefit for this role; A1 provides general benefit for this role; I1 provides general benefit for this role; R1.1 provides general benefit for this role. | N9: [GN] combine with "Advanced_Data_Analysis_and_Insights_Professiona". | O9: Issues: Unexpected issues in source data; lack of documentation or metadata in source data; problems with workflows, pipelines, or models. Latent gains: implementing FAIR principles would reduce these challenges and unlock efficiency, compliance, and reuse. | P9: F1 ensures that reports are always built on unambiguous datasets with persistent identifiers, avoiding duplication of metrics; F2 provides metadata that makes it easier to understand the business meaning and quality of data, ensuring accurate reporting; A1 guarantees analysts have seamless access to the datasets they need, reducing delays in producing dashboards and KPIs; I1 allows combining data from different domains into integrated views for stakeholders; R1.1 assures that reports are reproducible and can be validated over time, strengthening trust in recurring insights.
A10: https://github.com/PistoiaAlliance/FAIRMaturityMatrix/blob/FAIR-MM-V1.2/FAIR_personas/Data_Owner.md | B10: Data_Owner | C10: Data Enabler | D10: Business-accountable role responsible for the value, quality, and compliance of a dataset} accountable for the data within a specific domain or dataset. This includes the quality, integrity, access control, compliance (to standards and FAIR) and usage policies of the data. [RS]: In the context of FAIR data principles, a Data Owner has both the legal rights and managerial responsibility for a dataset. The Data Owner is responsible for establishing policies on who can access and use the data, ensuring compliance with relevant laws and standards, and managing permissions. They oversee the assignment of metadata, documentation, and maintenance of data quality, while ultimately being accountable for the dataset’s proper stewardship, even if routine management is delegated to others, ensuring the data remains FAIR-compliant at all times. | E10: Kathleen R and, Nalini Mehta, Baptiste Tauzin | F10: https://datamanagement.wiki/role/data_owner https://www.gov.uk/government/publications/essential-shared-data-assets-and-data-ownership-in-government/data-ownership-in-government-html | G10: Business Data Owner; Data Asset Owner; Data Manager | H10: Business_Leader,Business_Owner,Business_Analyst,Data_Steward,Project_Manager | I10: Used at : Amgen, GSK | J10: { To review with group - V1.2 } | K10: [RS] : Oversees organizational data assets, setting and enforcing policies on data access, quality, security, and retention to align with business goals and compliance standards. Defines data governance protocols, approves data classifications, and manages risk by implementing security controls and evaluating threats. Approves changes to data systems, delegates stewardship tasks, and coordinates between business and technical teams. Promotes cross-functional collaboration, monitors data performance, provides advocacy and training on data governance, and manages resources to ensure robust, secure, and valuable data that supports strategic objectives and innovation. | L10: Challenges: Complexity in Data Governance: Coordinating and implementing consistent governance practices across various data domains can be challenging, leading to fragmented data policies. Data Quality Challenges: Ensuring high data quality and consistency requires constant oversight and access to adequate cleansing resources, which can be resource-intensive. Resistance to Change: Implementing data policies or systems may face resistance from stakeholders resistant to altering established workflows. Compliance and Regulatory Pressure: Keeping up with changing legal and regulatory requirements can be demanding and complex, requiring continuous update and monitoring. Cross-Functional Coordination: Building effective collaboration between technical teams and business units can be difficult, with potential misalignments in goals and communication barriers. Security Threats: Protecting data from security breaches requires ongoing vigilance and investment in new security technologies and practices. Budget Constraints: Limited resources may constrain the implementation of necessary data management improvements and technology upgrades. Integration Issues: Challenges in integrating new data systems with existing infrastructure can lead to inefficiencies or conflicts. Latent Gains: Enhanced Decision-Making: Effective data ownership can lead to improved data-driven decision-making, fostering innovation and strategic advancement. Improved Data Quality: Proactive data management leads to cleaner, more reliable, and higher-quality data, enhancing operational effectiveness. Compliance and Security: Robust data governance helps mitigate risks and ensures compliance with regulatory frameworks, protecting organizational integrity and reputation. Cross-Functional Collaboration: Enhanced alignment between teams improves communication, leading to more cohesive strategies and execution across business and IT functions. Cost Efficiency: Streamlining data processes and eliminating redundancies can lead to operational efficiencies and reduce costs over time. Competitive Advantage: By leveraging data effectively, organizations can gain a competitive edge through better market insights and customer understanding. Innovation Opportunities: Well-managed data opens doors to new opportunities for innovation, product development, and personalized customer experiences. Employee Empowerment: Training initiatives under data ownership can lead to higher data literacy, empowering employees to make informed decisions and contribute to strategic goals. By addressing these issues and pursuing latent gains, a Data Owner can significantly impact the organization's ability to manage data as a strategic asset, turning challenges into opportunities for growth and value creation. | M10: The FAIR principles are key guidelines for improving data management and harnessing the value of data assets. Implementing these principles can bring several potential benefits to an organization through the role of a Data Owner: Potential FAIR Benefits: 1. Findable: Enhanced Discoverability: By implementing standardized metadata and indexing, data becomes easily searchable, enabling stakeholders to quickly locate needed information. Efficient Data Utilization: Improved discoverability reduces time spent searching for data, allowing teams to focus on analysis and decision-making. 2. Accessible: Improved Data Sharing: Ensuring data accessibility through clearly defined protocols allows stakeholders across the organization to seamlessly access data, fostering collaboration. Transparent Permission Structures: Establishing clear data access protocols reduces confusion and enhances security by ensuring only authorized users can access sensitive data. 3. Interoperable: System Compatibility: Interoperable data can integrate across different systems and platforms, reducing silos and increasing data flow across functions. Enhanced Collaboration: It simplifies data collaboration both internally and externally with partners, as data can be easily shared and utilized in a variety of formats without technical barriers. 4. Reusable: Maximized Data Value: Data that is structured for reusability enhances its value by allowing teams to leverage it for multiple analyses and projects beyond its initial purpose. Sustainability: Reusable data facilitates long-term sustainability of data assets, reducing duplication of efforts and promoting efficient use of resources. Overall Benefits: Improved Efficiency and Productivity: By applying the FAIR principles, organizations can streamline data processes and enhance productivity across teams by facilitating easier access and utilization of information. Innovation and Strategic Insight: FAIR-aligned data management supports innovative uses of data, helping organizations develop new insights and strategic advances. Robust Data Governance: The principles reinforce comprehensive data governance, promoting consistency, compliance, and security across data assets. Reduced Costs: Efficient data management practices can reduce redundancies and minimize resource expenditure associated with data handling and storage. Integrating the FAIR principles through the role of a Data Owner can greatly enhance the organization's ability to leverage data assets effectively, turning them into a cornerstone for business growth and transformation. {()} {[( F1, A1, I1, R1.1 )]} – F1 provides general benefit for this role; A1 provides general benefit for this role; I1 provides general benefit for this role; R1.1 provides general benefit for this role. | N10: [GN] Seems to be a duplicate of Business_Owner/ - propose to park or remove (note: clarify which speficic FAIR principles are in scope) | O10: Issues: In a non-FAIR environment, Data Owners face unclear data visibility, inconsistent governance enforcement, poor metadata and lineage, and limited control over data reuse. This increases regulatory, security, and reputational risk, complicates accountability, weakens cross-functional coordination, and makes it difficult to demonstrate compliance, value, and proper stewardship of data assets. Latent Gains: | P10: F1 ensures datasets under ownership are persistently identified, enabling clear accountability and traceability; F2 provides rich metadata that demonstrates the dataset’s purpose, scope, and quality to consumers; A1 guarantees reliable access controls so the owner can manage who uses the dataset; I1 enables interoperability with other organizational datasets, increasing business value; R1.1 assures reproducibility of results generated from the dataset, reinforcing trust in its use; R1.2 provides clarity on reuse through explicit licensing, reducing risks and negotiations for the data owner.
A11: https://github.com/PistoiaAlliance/FAIRMaturityMatrix/blob/FAIR-MM-V1.2/FAIR_personas/Data_Protection_Officer.md | B11: Data_Protection_Officer | C11: Data Enabler | D11: Ensures compliance with privacy, regulatory, and security requirements. | E11: Birgit Meldal | F11: Copilot; https://www.wikidata.org/wiki/Q30682903 | G11: Data Privacy Officer; Data Security Officer | H11: Business_Leader,Data_Owner,Data_Steward | I11: {nice to have/ to complete} | J11: { To review with group - V1.2 } | K11: Ensures that research, clinical, and operational data practices comply with GDPR, HIPAA, and other international regulations. Their tasks include reviewing data governance policies, monitoring cross-border data transfers, and advising R&D and IT teams, e.g. on privacy-by-design practices. They work closely with clinical operations to oversee the lawful use of patient and trial data, ensuring consent and data-use conditions are accurately captured and respected. Conducts regular audits, risk assessments, and staff training to reinforce compliance culture across the organization. Act as the bridge between regulators, business leaders, and scientists, balancing the drive for data sharing and data-driven innovation with the company’s obligations to protect privacy, security, and trust. | L11: risk of data breaches if data management doesn't include security at all levels | M11: Data may be FAIR on paper but cannot be used widely without the right security measures - esp for propriatory and data and data containing – A1.2 guarantees controlled access for privacy compliance; R1.1 ensures reproducible compliance evidence. | N11: (needs better descrpitons) | O11: Issues: risk of data breaches if data management doesn't include security at all levels. Latent gains: implementing FAIR principles would reduce these challenges and unlock efficiency, compliance, and reuse. | P11: A1.2 enforces controlled access for privacy compliance; R1.1 guarantees reproducibility of compliance evidence
A12: https://github.com/PistoiaAlliance/FAIRMaturityMatrix/blob/FAIR-MM-V1.2/FAIR_personas/Data_Scientist.md | B12: Data_Scientist | C12: Data Producer | D12: Data Scientists find, compile, clean, preprocess and analyze complex datasets. They interpret data trends, develop predictive models, and communicate findings to inform strategic decision-making. Data Scientists also design experiments, possess expertise in statistical methods, programming, data visualization, database management, and may have domain-specific knowledge. See also “researcher” . | E12: giovanni nisato | F12: https://pistoiaalliance.github.io/FAIRMaturityMatrix/resources_lexicon | G12: R&D Data Scientist; Computational Scientist; Bioinformatician; Machine Learning Engineer; Quantitative Analyst; Applied Data Scientist; AI/ML Scientist; | H12: Advanced_Data_Analysis_and_Insights_Professional,Citizen_Data_Scientist,Researcher,Data_Analyst,Data_Engineer | I12: Used at: Novartis, GSK | J12: FAIRMM_V1.1 | K12: Performs analysis of R&D and clinical data, integrating diverse sources such as omics datasets (RNAseq, DNAseq, proteomics, metabolomics), digital pathology images, and real-world evidence. Cleans, harmonizes, and preprocesses complex data to ensure quality and consistency. Applies statistical and computational methods to uncover biological mechanisms, identify biomarkers, and support target discovery, patient stratification, and clinical outcome prediction. Collaborates with bioinformaticians, biostatisticians, and domain experts to interpret results and translate findings into actionable insights for drug discovery and development. | L12: Issues: different, inconsistent ontologies and spread out across different sources and sometimes not knowing that they are existing | M12: FAIR data transforms the way research and analysis are conducted. When data is Findable, Accessible, Interoperable, and Reusable, it eliminates one of the greatest barriers to scientific progress—the time lost searching for, cleaning, and reconciling fragmented datasets. FAIR data allows Data Scientists to quickly discover high-quality, well-annotated datasets across R&D, clinical, and real-world domains, accelerating hypothesis generation and model development. Interoperable data formats and shared standards enable seamless integration of diverse data types—from omics and imaging to patient and assay data—allowing deeper, more holistic analyses. Reusable datasets and documented workflows enhance reproducibility, making results easier to validate and build upon. Ultimately, FAIR data empowers Data Scientists to focus less on data wrangling and more on interpreting results, generating insights, and driving data-informed decisions that advance discovery, improve clinical outcomes, and reduce development timelines. | N12: must have | O12: Issues: Issues: different, inconsistent ontologies and spread out across different sources and sometimes not knowing that they are existing. Latent gains: implementing FAIR principles would reduce these challenges and unlock efficiency, compliance, and reuse. | P12: F1 guarantees persistent identifiers to trace datasets across workflows; F2 provides rich metadata that makes datasets discoverable and interpretable; A1 ensures stable access for computational pipelines; I1 supports integration of heterogeneous datasets for machine learning; R1.1 ensures reproducibility of models and analyses across studies
A13: https://github.com/PistoiaAlliance/FAIRMaturityMatrix/blob/FAIR-MM-V1.2/FAIR_personas/Data_Standards_and_Governance_Expert.md | B13: Data_Standards_and_Governance_Expert | C13: Data Enabler | D13: Acts as a governance advisor and facilitator, ensuring the adoption and compliance of data standards across the organization. Provides expertise on data standards and governance within a specific business function. Defines how data is managed, protected, and used across the enterprise by establishing policies, standards, and roles that ensure data is accurate, secure, compliant with regulations, and aligned with business objectives. | E13: giovanni.nisato@pistoiaalliance.org/ Emiliano Reynares | F13: Email communication / FAIR-for-pharma | G13: Policy Maker; Data Governance Lead; Information Governance Manager; Policy Owner | H13: Business_Analyst,Data_Owner,Data_Steward,Researcher | I13: {nice to have/ to complete} | J13: { To review with group - V1.2 } | K13: ensures consistent, compliant, and interoperable data practices across research and manufacturing. Working with scientists and technical teams, the expert defines and maintains controlled vocabularies and standardized term lists for Laboratory Information Management Systems (LIMS) and Manufacturing Execution Systems (MES), ensuring methods, processes, and data are recorded in FAIR-compliant formats before integration into central databases. In production contexts such as tablet manufacturing, the expert applies the ISA-88 (S88) standard to structure and harmonize process data. The role defines and enforces policies for data quality, security, privacy, and usage; assigns ownership and stewardship responsibilities; and ensures compliance with internal standards and external regulations. The expert maintains visibility of data provenance and lineage to ensure traceability and trust, promotes adoption of governance frameworks across business and technical functions, and monitors the effectiveness of data standards to support reliable, reusable, and regulatory-ready information. | L13: The main issues are convincing the scientific departments to put the time in up front to deliver a benefit they can’t directly see. | M13: FAIR principles transforms data governance from a compliance obligation into a strategic enabler of efficiency, quality, and trust. FAIR ensures that data is findable and discoverable across systems, reducing duplication and enabling reuse of validated information. Accessibility allows authorized users to retrieve data seamlessly within compliant frameworks, while interoperability enables consistent data exchange across instruments, laboratories, and business units without loss of meaning—directly supporting harmonization of LIMS, MES, and enterprise data models. Reusability extends the value of high-quality, well-documented data, improving reproducibility, regulatory readiness, and analytics potential. For this expert, FAIR provides a concrete framework to drive standardization, traceability, and continuous improvement, turning governance into a catalyst for innovation and long-term organizational learning. | N13: [GN] - check if must have. / overal with Legal data and ontology experts ? | O13: Issues: Convincing scientists to invest time upfront in structured data capture remains the main hurdle. Benefits of FAIR are not immediately visible, leading to resistance and inconsistent adoption. Metadata entry is seen as extra work; tools and vocabularies remain fragmented across LIMS, MES, and ELN systems. Legacy data, unclear ownership, and competing standards add friction, while governance enforcement and balancing compliance with usability continue to challenge implementation. Latent gains: Once FAIR principles are embedded, data becomes findable, traceable, and reusable across research and manufacturing. Efficiency improves through reduced duplication and faster access to validated information. Compliance and audit readiness strengthen through clear provenance and standardization. Harmonized data flows enable interoperability, AI-driven analytics, and sustained knowledge reuse—turning governance from a control mechanism into a catalyst for scientific productivity and long-term data value. | P13: F1 provides persistent identifiers that governance experts can mandate to ensure data is consistently referenced across the organization; F2 enriches metadata so governance frameworks can require transparency and completeness; A1 guarantees that access protocols are standardized, making governance policies easier to enforce; I1 ensures interoperability across domains, allowing governance rules to scale enterprise-wide; R1.3 promotes reuse of data aligned with recognized community and industry standards, reinforcing organizational compliance and credibility.
